Workbook

Sheet Cover
A1: CacheCow / ForcedField Technologies
A2: 5-Year Financial Model
A3: Confidential — April 2026
A5: Scenario: | B5: Base
A7: Table of Contents
A8: 1. Cover | B8: Overview and scenario selector
A9: 2. Assumptions | B9: All model inputs and parameters
A10: 3. Revenue Buildup | B10: Revenue by stream, Y1-Y5
A11: 4. P&L | B11: Profit & Loss statement
A12: 5. Unit Economics | B12: Per-device and per-ranch metrics
A13: 6. Scenarios | B13: Conservative / Base / Optimistic comparison
A14: 7. Cash Flow | B14: Operating cash flow and runway
A15: 8. Cap Table | B15: Ownership through Seed, A, B
A16: 9. Charts | B16: Visual dashboards

Sheet Assumptions
A2: Device & Pricing
A3: Device Unit Price ($) | B3: 95
A4: Annual Subscription ($/animal/yr) | B4: 50
A5: Hardware COGS per Device ($) | B5: 33
A6: Subscription COGS per Animal/yr ($) | B6: 17.5
A7: Hardware Gross Margin | B7: =(B3-B5)/B3
A8: Subscription Gross Margin | B8: =(B4-B6)/B4
A10: Deployment Schedule
B11: Year 1 | C11: Year 2 | D11: Year 3 | E11: Year 4 | F11: Year 5
A12: Devices Deployed (Cumulative) | B12: 10000 | C12: 200000 | D12: 500000 | E12: 750000 | F12: 1000000
A13: Net New Devices | B13: 10000 | C13: 190000 | D13: 300000 | E13: 250000 | F13: 250000
A14: Annual Churn Rate | B14: 0.02 | C14: 0.02 | D14: 0.02 | E14: 0.02 | F14: 0.02
A15: Active Devices (End of Year) | B15: =B13 | C15: =B15*(1-C14)+C13 | D15: =C15*(1-D14)+D13 | E15: =D15*(1-E14)+E13 | F15: =E15*(1-F14)+F13
A17: Revenue Layer Activation
B18: Year 1 | C18: Year 2 | D18: Year 3 | E18: Year 4 | F18: Year 5
A19: Hardware + Subscription | B19: 1 | C19: 1 | D19: 1 | E19: 1 | F19: 1
A20: Data Licensing | B20: 0 | C20: 1 | D20: 1 | E20: 1 | F20: 1
A21: Platform IP | B21: 0 | C21: 0 | D21: 1 | E21: 1 | F21: 1
A23: Weather Participation Rates
A24: Conservative | B24: 0.1
A25: Base | B25: 0.2
A26: Optimistic | B26: 0.3
A28: Data Licensing
A29: Addressable TAM at Scale ($) | B29: 60000000
A30: Data Licensing per Device/yr (Base, $) | B30: 15
A31: Revenue Share to Ranchers | B31: 0.15
A33: Platform IP Licensing
A34: IP License Deals Y3 | B34: 2
A35: IP License Deals Y4 | B35: 5
A36: IP License Deals Y5 | B36: 12
A37: Avg Deal Size ($) | B37: 0 | C37: 0 | D37: 500000 | E37: 1000000 | F37: 2000000
A38: IP Deals by Year | B38: 0 | C38: 0 | D38: 2 | E38: 5 | F38: 12
A39: Operating Expenses
B40: Year 1 | C40: Year 2 | D40: Year 3 | E40: Year 4 | F40: Year 5
A41: Headcount | B41: 5 | C41: 12 | D41: 30 | E41: 60 | F41: 100
A42: Avg Salary ($) | B42: 120000 | C42: 126000 | D42: 132300 | E42: 138915 | F42: 145861
A43: Total People Cost ($) | B43: =B41*B42*1.3 | C43: =C41*C42*1.3 | D43: =D41*D42*1.3 | E43: =E41*E42*1.3 | F43: =F41*F42*1.3
A44: R&D % of Revenue | B44: 0.4 | C44: 0.35 | D44: 0.3 | E44: 0.27 | F44: 0.25
A45: S&M % of Revenue | B45: 0.15 | C45: 0.18 | D45: 0.2 | E45: 0.18 | F45: 0.15
A46: G&A % of Revenue | B46: 0.15 | C46: 0.12 | D46: 0.1 | E46: 0.1 | F46: 0.1
...

Sheet Revenue Buildup
A1: Revenue Buildup
B2: Year 1 | C2: Year 2 | D2: Year 3 | E2: Year 4 | F2: Year 5
A3: HARDWARE + SUBSCRIPTION
A4: Hardware Revenue | B4: =Assumptions!B13*Assumptions!B3*Assumptions!B19 | C4: =Assumptions!C13*Assumptions!B3*Assumptions!C19 | D4: =Assumptions!D13*Assumptions!B3*Assumptions!D19 | E4: =Assumptions!E13*Assumptions!B3*Assumptions!E19 | F4: =Assumptions!F13*Assumptions!B3*Assumptions!F19
A5: Subscription Revenue | B5: =Assumptions!B15*Assumptions!B4*Assumptions!B19 | C5: =Assumptions!C15*Assumptions!B4*Assumptions!C19 | D5: =Assumptions!D15*Assumptions!B4*Assumptions!D19 | E5: =Assumptions!E15*Assumptions!B4*Assumptions!E19 | F5: =Assumptions!F15*Assumptions!B4*Assumptions!F19
A6: Total H+S Revenue | B6: =B4+B5 | C6: =C4+C5 | D6: =D4+D5 | E6: =E4+E5 | F6: =F4+F5
A9: DATA LICENSING
A11: Eligible Devices | B11: =Assumptions!B15*Assumptions!B20 | C11: =Assumptions!C15*Assumptions!C20 | D11: =Assumptions!D15*Assumptions!D20 | E11: =Assumptions!E15*Assumptions!E20 | F11: =Assumptions!F15*Assumptions!F20
A12: Data Revenue (Gross) | B12: =B11*Assumptions!B30 | C12: =C11*Assumptions!B30 | D12: =D11*Assumptions!B30 | E12: =E11*Assumptions!B30 | F12: =F11*Assumptions!B30
A13: Rancher Revenue Share | B13: =B12*Assumptions!B31 | C13: =C12*Assumptions!B31 | D13: =D12*Assumptions!B31 | E13: =E12*Assumptions!B31 | F13: =F12*Assumptions!B31
A14: Net Data Revenue | B14: =B12-B13 | C14: =C12-C13 | D14: =D12-D13 | E14: =E12-E13 | F14: =F12-F13
A16: WEATHER DATA
A17: Weather-Active Devices | B17: =Assumptions!B15*Assumptions!B25 | C17: =Assumptions!C15*Assumptions!B25 | D17: =Assumptions!D15*Assumptions!B25 | E17: =Assumptions!E15*Assumptions!B25 | F17: =Assumptions!F15*Assumptions!B25
A18: Weather License Revenue | B18: 0 | C18: 8000000 | D18: 21500000 | E18: 35000000 | F18: 50000000
A19: Ground Truth Premium | B19: =B18*0.25 | C19: =C18*0.25 | D19: =D18*0.25 | E19: =E18*0.25 | F19: =F18*0.25
A20: Total Weather Revenue | B20: =B18+B19 | C20: =C18+C19 | D20: =D18+D19 | E20: =E18+E19 | F20: =F18+F19
A22: PLATFORM IP LICENSING
A23: License Deals | B23: =Assumptions!B38 | C23: =Assumptions!C38 | D23: =Assumptions!D38 | E23: =Assumptions!E38 | F23: =Assumptions!F38
A24: Platform IP Revenue | B24: =B23*Assumptions!B37*Assumptions!B21 | C24: =C23*Assumptions!C37*Assumptions!C21 | D24: =D23*Assumptions!D37*Assumptions!D21 | E24: =E23*Assumptions!E37*Assumptions!E21 | F24: =F23*Assumptions!F37*Assumptions!F21
A28: TOTAL REVENUE | B28: =B6+B14+B20+B24 | C28: =C6+C14+C20+C24 | D28: =D6+D14+D20+D24 | E28: =E6+E14+E20+E24 | F28: =F6+F14+F20+F24

Sheet P&L
A1: Profit & Loss
B2: Year 1 | C2: Year 2 | D2: Year 3 | E2: Year 4 | F2: Year 5
A3: Total Revenue | B3: ='Revenue Buildup'!B28 | C3: ='Revenue Buildup'!C28 | D3: ='Revenue Buildup'!D28 | E3: ='Revenue Buildup'!E28 | F3: ='Revenue Buildup'!F28
A5: Hardware COGS | B5: =Assumptions!B13*Assumptions!B5 | C5: =Assumptions!C13*Assumptions!B5 | D5: =Assumptions!D13*Assumptions!B5 | E5: =Assumptions!E13*Assumptions!B5 | F5: =Assumptions!F13*Assumptions!B5
A6: Subscription COGS | B6: =Assumptions!B15*Assumptions!B6 | C6: =Assumptions!C15*Assumptions!B6 | D6: =Assumptions!D15*Assumptions!B6 | E6: =Assumptions!E15*Assumptions!B6 | F6: =Assumptions!F15*Assumptions!B6
A7: Data COGS | B7: ='Revenue Buildup'!B14*(1-Assumptions!B59) | C7: ='Revenue Buildup'!C14*(1-Assumptions!B59) | D7: ='Revenue Buildup'!D14*(1-Assumptions!B59) | E7: ='Revenue Buildup'!E14*(1-Assumptions!B59) | F7: ='Revenue Buildup'!F14*(1-Assumptions!B59)
A8: Weather COGS | B8: ='Revenue Buildup'!B20*(1-Assumptions!B61) | C8: ='Revenue Buildup'!C20*(1-Assumptions!B61) | D8: ='Revenue Buildup'!D20*(1-Assumptions!B61) | E8: ='Revenue Buildup'!E20*(1-Assumptions!B61) | F8: ='Revenue Buildup'!F20*(1-Assumptions!B61)
A9: Platform COGS | B9: ='Revenue Buildup'!B24*(1-Assumptions!B60) | C9: ='Revenue Buildup'!C24*(1-Assumptions!B60) | D9: ='Revenue Buildup'!D24*(1-Assumptions!B60) | E9: ='Revenue Buildup'!E24*(1-Assumptions!B60) | F9: ='Revenue Buildup'!F24*(1-Assumptions!B60)
A10: Total COGS | B10: =B5+B6+B7+B8+B9 | C10: =C5+C6+C7+C8+C9 | D10: =D5+D6+D7+D8+D9 | E10: =E5+E6+E7+E8+E9 | F10: =F5+F6+F7+F8+F9
A12: Gross Profit | B12: =B3-B10 | C12: =C3-C10 | D12: =D3-D10 | E12: =E3-E10 | F12: =F3-F10
A13: Gross Margin % | B13: =IF(B3=0,0,B12/B3) | C13: =IF(C3=0,0,C12/C3) | D13: =IF(D3=0,0,D12/D3) | E13: =IF(E3=0,0,E12/E3) | F13: =IF(F3=0,0,F12/F3)
A15: R&D Expense | B15: =MAX(B3*Assumptions!B44, Assumptions!B43*0.6) | C15: =MAX(C3*Assumptions!C44, Assumptions!C43*0.6) | D15: =MAX(D3*Assumptions!D44, Assumptions!D43*0.6) | E15: =MAX(E3*Assumptions!E44, Assumptions!E43*0.6) | F15: =MAX(F3*Assumptions!F44, Assumptions!F43*0.6)
A16: Sales & Marketing | B16: =B3*Assumptions!B45 | C16: =C3*Assumptions!C45 | D16: =D3*Assumptions!D45 | E16: =E3*Assumptions!E45 | F16: =F3*Assumptions!F45
A17: G&A Expense | B17: =B3*Assumptions!B46 | C17: =C3*Assumptions!C46 | D17: =D3*Assumptions!D46 | E17: =E3*Assumptions!E46 | F17: =F3*Assumptions!F46
A18: Total OpEx | B18: =B15+B16+B17 | C18: =C15+C16+C17 | D18: =D15+D16+D17 | E18: =E15+E16+E17 | F18: =F15+F16+F17
A20: EBITDA | B20: =B12-B18 | C20: =C12-C18 | D20: =D12-D18 | E20: =E12-E18 | F20: =F12-F18
A21: EBITDA Margin % | B21: =IF(B3=0,0,B20/B3) | C21: =IF(C3=0,0,C20/C3) | D21: =IF(D3=0,0,D20/D3) | E21: =IF(E3=0,0,E20/E3) | F21: =IF(F3=0,0,F20/F3)
A23: Depreciation & Amortization | B23: 100000 | C23: 300000 | D23: 500000 | E23: 750000 | F23: 1000000
A24: Net Income | B24: =B20-B23 | C24: =C20-C23 | D24: =D20-D23 | E24: =E20-E23 | F24: =F20-F23

Sheet Unit Economics
A1: Unit Economics
B2: Year 1 | C2: Year 2 | D2: Year 3 | E2: Year 4 | F2: Year 5
A3: Revenue per Active Device | B3: ='P&L'!B3/Assumptions!B15 | C3: ='P&L'!C3/Assumptions!C15 | D3: ='P&L'!D3/Assumptions!D15 | E3: ='P&L'!E3/Assumptions!E15 | F3: ='P&L'!F3/Assumptions!F15
A4: COGS per Active Device | B4: ='P&L'!B10/Assumptions!B15 | C4: ='P&L'!C10/Assumptions!C15 | D4: ='P&L'!D10/Assumptions!D15 | E4: ='P&L'!E10/Assumptions!E15 | F4: ='P&L'!F10/Assumptions!F15
A5: Gross Profit per Device | B5: =B3-B4 | C5: =C3-C4 | D5: =D3-D4 | E5: =E3-E4 | F5: =F3-F4
A6: Total OpEx per Device | B6: ='P&L'!B18/Assumptions!B15 | C6: ='P&L'!C18/Assumptions!C15 | D6: ='P&L'!D18/Assumptions!D15 | E6: ='P&L'!E18/Assumptions!E15 | F6: ='P&L'!F18/Assumptions!F15
A7: Contribution Margin per Device | B7: =B5-B6 | C7: =C5-C6 | D7: =D5-D6 | E7: =E5-E6 | F7: =F5-F6
A9: Implied Ranch Count (1000 hd avg) | B9: =Assumptions!B15/1000 | C9: =Assumptions!C15/1000 | D9: =Assumptions!D15/1000 | E9: =Assumptions!E15/1000 | F9: =Assumptions!F15/1000
A10: Revenue per Ranch | B10: =IF(B9=0,0,'P&L'!B3/B9) | C10: =IF(C9=0,0,'P&L'!C3/C9) | D10: =IF(D9=0,0,'P&L'!D3/D9) | E10: =IF(E9=0,0,'P&L'!E3/E9) | F10: =IF(F9=0,0,'P&L'!F3/F9)
A11: LTV per Ranch (10yr) | B11: =B10*10*'P&L'!B13 | C11: =C10*10*'P&L'!C13 | D11: =D10*10*'P&L'!D13 | E11: =E10*10*'P&L'!E13 | F11: =F10*10*'P&L'!F13
A12: Estimated CAC per Ranch | B12: =IF(Assumptions!B13=0,0,'P&L'!B16/(Assumptions!B13/1000)) | C12: =IF(Assumptions!C13=0,0,'P&L'!C16/(Assumptions!C13/1000)) | D12: =IF(Assumptions!D13=0,0,'P&L'!D16/(Assumptions!D13/1000)) | E12: =IF(Assumptions!E13=0,0,'P&L'!E16/(Assumptions!E13/1000)) | F12: =IF(Assumptions!F13=0,0,'P&L'!F16/(Assumptions!F13/1000))
A13: LTV:CAC Ratio | B13: =IF(B12=0,0,B11/B12) | C13: =IF(C12=0,0,C11/C12) | D13: =IF(D12=0,0,D11/D12) | E13: =IF(E12=0,0,E11/E12) | F13: =IF(F12=0,0,F11/F12)
A14: Payback Period (months) | B14: =IF(B10=0,0,B12/((B10/12)*'P&L'!B13)) | C14: =IF(C10=0,0,C12/((C10/12)*'P&L'!C13)) | D14: =IF(D10=0,0,D12/((D10/12)*'P&L'!D13)) | E14: =IF(E10=0,0,E12/((E10/12)*'P&L'!E13)) | F14: =IF(F10=0,0,F12/((F10/12)*'P&L'!F13))

Sheet Scenarios
A1: Scenario Analysis
B2: Conservative | H2: Base | N2: Optimistic
B3: Year 1 | C3: Year 2 | D3: Year 3 | E3: Year 4 | F3: Year 5 | H3: Year 1 | I3: Year 2 | J3: Year 3 | K3: Year 4 | L3: Year 5 | N3: Year 1 | O3: Year 2 | P3: Year 3 | Q3: Year 4 | R3: Year 5
A4: Active Devices | B4: =Assumptions!B15*0.7 | C4: =Assumptions!C15*0.7 | D4: =Assumptions!D15*0.7 | E4: =Assumptions!E15*0.7 | F4: =Assumptions!F15*0.7 | H4: =Assumptions!B15*1.0 | I4: =Assumptions!C15*1.0 | J4: =Assumptions!D15*1.0 | K4: =Assumptions!E15*1.0 | L4: =Assumptions!F15*1.0 | N4: =Assumptions!B15*1.3 | O4: =Assumptions!C15*1.3 | P4: =Assumptions!D15*1.3 | Q4: =Assumptions!E15*1.3 | R4: =Assumptions!F15*1.3
A5: Total Revenue | B5: ='Revenue Buildup'!B6*0.7+'Revenue Buildup'!B14*0.7+'Revenue Buildup'!B20*(Assumptions!B24/Assumptions!B25)+'Revenue Buildup'!B24 | C5: ='Revenue Buildup'!C6*0.7+'Revenue Buildup'!C14*0.7+'Revenue Buildup'!C20*(Assumptions!B24/Assumptions!B25)+'Revenue Buildup'!C24 | D5: ='Revenue Buildup'!D6*0.7+'Revenue Buildup'!D14*0.7+'Revenue Buildup'!D20*(Assumptions!B24/Assumptions!B25)+'Revenue Buildup'!D24 | E5: ='Revenue Buildup'!E6*0.7+'Revenue Buildup'!E14*0.7+'Revenue Buildup'!E20*(Assumptions!B24/Assumptions!B25)+'Revenue Buildup'!E24 | F5: ='Revenue Buildup'!F6*0.7+'Revenue Buildup'!F14*0.7+'Revenue Buildup'!F20*(Assumptions!B24/Assumptions!B25)+'Revenue Buildup'!F24 | H5: ='Revenue Buildup'!B28 | I5: ='Revenue Buildup'!C28 | J5: ='Revenue Buildup'!D28 | K5: ='Revenue Buildup'!E28 | L5: ='Revenue Buildup'!F28 | N5: ='Revenue Buildup'!B6*1.3+'Revenue Buildup'!B14*1.3+'Revenue Buildup'!B20*(Assumptions!B26/Assumptions!B25)+'Revenue Buildup'!B24 | O5: ='Revenue Buildup'!C6*1.3+'Revenue Buildup'!C14*1.3+'Revenue Buildup'!C20*(Assumptions!B26/Assumptions!B25)+'Revenue Buildup'!C24 | P5: ='Revenue Buildup'!D6*1.3+'Revenue Buildup'!D14*1.3+'Revenue Buildup'!D20*(Assumptions!B26/Assumptions!B25)+'Revenue Buildup'!D24 | Q5: ='Revenue Buildup'!E6*1.3+'Revenue Buildup'!E14*1.3+'Revenue Buildup'!E20*(Assumptions!B26/Assumptions!B25)+'Revenue Buildup'!E24 | R5: ='Revenue Buildup'!F6*1.3+'Revenue Buildup'!F14*1.3+'Revenue Buildup'!F20*(Assumptions!B26/Assumptions!B25)+'Revenue Buildup'!F24
A6: Gross Profit | B6: =IF('P&L'!B3=0,0,B5*('P&L'!B12/'P&L'!B3)) | C6: =IF('P&L'!C3=0,0,C5*('P&L'!C12/'P&L'!C3)) | D6: =IF('P&L'!D3=0,0,D5*('P&L'!D12/'P&L'!D3)) | E6: =IF('P&L'!E3=0,0,E5*('P&L'!E12/'P&L'!E3)) | F6: =IF('P&L'!F3=0,0,F5*('P&L'!F12/'P&L'!F3)) | H6: =IF('P&L'!B3=0,0,H5*('P&L'!B12/'P&L'!B3)) | I6: =IF('P&L'!C3=0,0,I5*('P&L'!C12/'P&L'!C3)) | J6: =IF('P&L'!D3=0,0,J5*('P&L'!D12/'P&L'!D3)) | K6: =IF('P&L'!E3=0,0,K5*('P&L'!E12/'P&L'!E3)) | L6: =IF('P&L'!F3=0,0,L5*('P&L'!F12/'P&L'!F3)) | N6: =IF('P&L'!B3=0,0,N5*('P&L'!B12/'P&L'!B3)) | O6: =IF('P&L'!C3=0,0,O5*('P&L'!C12/'P&L'!C3)) | P6: =IF('P&L'!D3=0,0,P5*('P&L'!D12/'P&L'!D3)) | Q6: =IF('P&L'!E3=0,0,Q5*('P&L'!E12/'P&L'!E3)) | R6: =IF('P&L'!F3=0,0,R5*('P&L'!F12/'P&L'!F3))
A7: EBITDA | B7: =IF('P&L'!B3=0,0,B5*('P&L'!B20/'P&L'!B3)) | C7: =IF('P&L'!C3=0,0,C5*('P&L'!C20/'P&L'!C3)) | D7: =IF('P&L'!D3=0,0,D5*('P&L'!D20/'P&L'!D3)) | E7: =IF('P&L'!E3=0,0,E5*('P&L'!E20/'P&L'!E3)) | F7: =IF('P&L'!F3=0,0,F5*('P&L'!F20/'P&L'!F3)) | H7: =IF('P&L'!B3=0,0,H5*('P&L'!B20/'P&L'!B3)) | I7: =IF('P&L'!C3=0,0,I5*('P&L'!C20/'P&L'!C3)) | J7: =IF('P&L'!D3=0,0,J5*('P&L'!D20/'P&L'!D3)) | K7: =IF('P&L'!E3=0,0,K5*('P&L'!E20/'P&L'!E3)) | L7: =IF('P&L'!F3=0,0,L5*('P&L'!F20/'P&L'!F3)) | N7: =IF('P&L'!B3=0,0,N5*('P&L'!B20/'P&L'!B3)) | O7: =IF('P&L'!C3=0,0,O5*('P&L'!C20/'P&L'!C3)) | P7: =IF('P&L'!D3=0,0,P5*('P&L'!D20/'P&L'!D3)) | Q7: =IF('P&L'!E3=0,0,Q5*('P&L'!E20/'P&L'!E3)) | R7: =IF('P&L'!F3=0,0,R5*('P&L'!F20/'P&L'!F3))
A8: Net Income | B8: =IF('P&L'!B3=0,0,B5*('P&L'!B24/'P&L'!B3)) | C8: =IF('P&L'!C3=0,0,C5*('P&L'!C24/'P&L'!C3)) | D8: =IF('P&L'!D3=0,0,D5*('P&L'!D24/'P&L'!D3)) | E8: =IF('P&L'!E3=0,0,E5*('P&L'!E24/'P&L'!E3)) | F8: =IF('P&L'!F3=0,0,F5*('P&L'!F24/'P&L'!F3)) | H8: =IF('P&L'!B3=0,0,H5*('P&L'!B24/'P&L'!B3)) | I8: =IF('P&L'!C3=0,0,I5*('P&L'!C24/'P&L'!C3)) | J8: =IF('P&L'!D3=0,0,J5*('P&L'!D24/'P&L'!D3)) | K8: =IF('P&L'!E3=0,0,K5*('P&L'!E24/'P&L'!E3)) | L8: =IF('P&L'!F3=0,0,L5*('P&L'!F24/'P&L'!F3)) | N8: =IF('P&L'!B3=0,0,N5*('P&L'!B24/'P&L'!B3)) | O8: =IF('P&L'!C3=0,0,O5*('P&L'!C24/'P&L'!C3)) | P8: =IF('P&L'!D3=0,0,P5*('P&L'!D24/'P&L'!D3)) | Q8: =IF('P&L'!E3=0,0,Q5*('P&L'!E24/'P&L'!E3)) | R8: =IF('P&L'!F3=0,0,R5*('P&L'!F24/'P&L'!F3))
A9: Gross Margin % | B9: =IF(B5=0,0,B6/B5) | C9: =IF(C5=0,0,C6/C5) | D9: =IF(D5=0,0,D6/D5) | E9: =IF(E5=0,0,E6/E5) | F9: =IF(F5=0,0,F6/F5) | H9: =IF(H5=0,0,H6/H5) | I9: =IF(I5=0,0,I6/I5) | J9: =IF(J5=0,0,J6/J5) | K9: =IF(K5=0,0,K6/K5) | L9: =IF(L5=0,0,L6/L5) | N9: =IF(N5=0,0,N6/N5) | O9: =IF(O5=0,0,O6/O5) | P9: =IF(P5=0,0,P6/P5) | Q9: =IF(Q5=0,0,Q6/Q5) | R9: =IF(R5=0,0,R6/R5)
A10: EBITDA Margin % | B10: =IF(B5=0,0,B7/B5) | C10: =IF(C5=0,0,C7/C5) | D10: =IF(D5=0,0,D7/D5) | E10: =IF(E5=0,0,E7/E5) | F10: =IF(F5=0,0,F7/F5) | H10: =IF(H5=0,0,H7/H5) | I10: =IF(I5=0,0,I7/I5) | J10: =IF(J5=0,0,J7/J5) | K10: =IF(K5=0,0,K7/K5) | L10: =IF(L5=0,0,L7/L5) | N10: =IF(N5=0,0,N7/N5) | O10: =IF(O5=0,0,O7/O5) | P10: =IF(P5=0,0,P7/P5) | Q10: =IF(Q5=0,0,Q7/Q5) | R10: =IF(R5=0,0,R7/R5)
A11: Revenue per Device | B11: =IF(B4=0,0,B5/B4) | C11: =IF(C4=0,0,C5/C4) | D11: =IF(D4=0,0,D5/D4) | E11: =IF(E4=0,0,E5/E4) | F11: =IF(F4=0,0,F5/F4) | H11: =IF(H4=0,0,H5/H4) | I11: =IF(I4=0,0,I5/I4) | J11: =IF(J4=0,0,J5/J4) | K11: =IF(K4=0,0,K5/K4) | L11: =IF(L4=0,0,L5/L4) | N11: =IF(N4=0,0,N5/N4) | O11: =IF(O4=0,0,O5/O4) | P11: =IF(P4=0,0,P5/P4) | Q11: =IF(Q4=0,0,Q5/Q4) | R11: =IF(R4=0,0,R5/R4)

Sheet Cash Flow
A1: Cash Flow Statement
B2: Year 1 | C2: Year 2 | D2: Year 3 | E2: Year 4 | F2: Year 5
A3: EBITDA | B3: ='P&L'!B20 | C3: ='P&L'!C20 | D3: ='P&L'!D20 | E3: ='P&L'!E20 | F3: ='P&L'!F20
A4: CapEx | B4: -500000 | C4: -2000000 | D4: -3000000 | E4: -4000000 | F4: -5000000
A5: Working Capital Changes | B5: -200000 | C5: -1000000 | D5: -1500000 | E5: -2000000 | F5: -2500000
A7: Operating Cash Flow | B7: =B3+B4+B5 | C7: =C3+C4+C5 | D7: =D3+D4+D5 | E7: =E3+E4+E5 | F7: =F3+F4+F5
A9: Fundraising Inflows | B9: 3500000 | C9: 15000000 | D9: 75000000 | E9: 0 | F9: 0
A10: Net Cash Flow | B10: =B7+B9 | C10: =C7+C9 | D10: =D7+D9 | E10: =E7+E9 | F10: =F7+F9
A12: Opening Cash | B12: 0 | C12: =B13 | D12: =C13 | E12: =D13 | F12: =E13
A13: Closing Cash | B13: =B12+B10 | C13: =C12+C10 | D13: =D12+D10 | E13: =E12+E10 | F13: =F12+F10
A15: Monthly Burn Rate | B15: =('P&L'!B18+ABS(B4))/12 | C15: =('P&L'!C18+ABS(C4))/12 | D15: =('P&L'!D18+ABS(D4))/12 | E15: =('P&L'!E18+ABS(E4))/12 | F15: =('P&L'!F18+ABS(F4))/12
A16: Runway (Months) | B16: =IF(B15=0,0,B13/B15) | C16: =IF(C15=0,0,C13/C15) | D16: =IF(D15=0,0,D13/D15) | E16: =IF(E15=0,0,E13/E15) | F16: =IF(F15=0,0,F13/F15)

Sheet Cap Table
A1: Cap Table
B2: Ownership % | C2: Amount ($) | D2: Valuation ($)
A3: Founders (Pre-Seed) | B3: 1
A4: Option Pool (carved out) | B4: 0.1
A5: Founders (Post-Pool) | B5: =B3-B4
A7: SEED ROUND | B7: Ownership % | C7: Amount ($) | D7: Valuation ($)
A8: Amount Raised | C8: =Assumptions!B51
A9: Pre-money Valuation | D9: =Assumptions!C51
A10: Post-money Valuation | D10: =C8+D9
A11: Seed Investors % | B11: =C8/D10
A12: Founders post-Seed | B12: =(1-B4-B11)
A13: Option Pool post-Seed | B13: =B4
A15: SERIES A | B15: Ownership % | C15: Amount ($) | D15: Valuation ($)
A16: Amount Raised | C16: =Assumptions!B52
A17: Pre-money Valuation | D17: =Assumptions!C52
A18: Post-money Valuation | D18: =C16+D17
A19: Series A Investors % | B19: =C16/D18
A20: Founders post-A (diluted) | B20: =B12*(1-B19)
A21: Seed Investors post-A (diluted) | B21: =B11*(1-B19)
A22: Option Pool post-A (diluted) | B22: =B13*(1-B19)
A24: SERIES B | B24: Ownership % | C24: Amount ($) | D24: Valuation ($)
A25: Amount Raised | C25: =Assumptions!B53
A26: Pre-money Valuation | D26: =Assumptions!C53
A27: Post-money Valuation | D27: =C25+D26
A28: Series B Investors % | B28: =C25/D27
A29: Founders post-B (diluted) | B29: =B20*(1-B28)
A30: Seed Investors post-B (diluted) | B30: =B21*(1-B28)
A31: Series A Investors post-B (diluted) | B31: =B19*(1-B28)
A32: Option Pool post-B (diluted) | B32: =B22*(1-B28)
A33: Series B Investors | B33: =B28
A35: TOTAL (verify = 100%) | B35: =B29+B30+B31+B32+B33

Sheet Charts
A2: Year | B2: Hardware+Sub | C2: Data Licensing | D2: Weather | E2: Platform IP
A3: Y1 | B3: ='Revenue Buildup'!B6 | C3: ='Revenue Buildup'!B14 | D3: ='Revenue Buildup'!B20 | E3: ='Revenue Buildup'!B24
A4: Y2 | B4: ='Revenue Buildup'!C6 | C4: ='Revenue Buildup'!C14 | D4: ='Revenue Buildup'!C20 | E4: ='Revenue Buildup'!C24
A5: Y3 | B5: ='Revenue Buildup'!D6 | C5: ='Revenue Buildup'!D14 | D5: ='Revenue Buildup'!D20 | E5: ='Revenue Buildup'!D24
A6: Y4 | B6: ='Revenue Buildup'!E6 | C6: ='Revenue Buildup'!E14 | D6: ='Revenue Buildup'!E20 | E6: ='Revenue Buildup'!E24
A7: Y5 | B7: ='Revenue Buildup'!F6 | C7: ='Revenue Buildup'!F14 | D7: ='Revenue Buildup'!F20 | E7: ='Revenue Buildup'!F24
G10: Year | H10: Conservative | I10: Base | J10: Optimistic
G11: Y1 | H11: =Scenarios!B5 | I11: =Scenarios!H5 | J11: =Scenarios!N5
G12: Y2 | H12: =Scenarios!C5 | I12: =Scenarios!I5 | J12: =Scenarios!O5
G13: Y3 | H13: =Scenarios!D5 | I13: =Scenarios!J5 | J13: =Scenarios!P5
G14: Y4 | H14: =Scenarios!E5 | I14: =Scenarios!K5 | J14: =Scenarios!Q5
G15: Y5 | H15: =Scenarios!F5 | I15: =Scenarios!L5 | J15: =Scenarios!R5
A18: Year | B18: Gross Margin %
A19: Y1 | B19: ='P&L'!B13
A20: Y2 | B20: ='P&L'!C13
A21: Y3 | B21: ='P&L'!D13
A22: Y4 | B22: ='P&L'!E13
A23: Y5 | B23: ='P&L'!F13
G25: Year | H25: Closing Cash
G26: Y1 | H26: ='Cash Flow'!B13
G27: Y2 | H27: ='Cash Flow'!C13
G28: Y3 | H28: ='Cash Flow'!D13
G29: Y4 | H29: ='Cash Flow'!E13
G30: Y5 | H30: ='Cash Flow'!F13
A33: Year | B33: Cumulative Devices
A34: Y1 | B34: =Assumptions!B12
A35: Y2 | B35: =Assumptions!C12
A36: Y3 | B36: =Assumptions!D12
A37: Y4 | B37: =Assumptions!E12
A38: Y5 | B38: =Assumptions!F12
